2022-04-26 16:04:58 base.py[line:166] INFO Scheduler started
2022-04-26 16:05:08 base.py[line:166] INFO Scheduler started
2022-04-26 16:05:18 base.py[line:166] INFO Scheduler started
2022-04-26 16:07:17 autoreload.py[line:236] INFO /Users/wuhongbin/Desktop/养乐多/lwjTest/manage.py changed, reloading.
2022-04-26 16:07:24 base.py[line:166] INFO Scheduler started
2022-04-26 16:07:29 base.py[line:166] INFO Scheduler started
2022-04-26 16:18:55 base.py[line:166] INFO Scheduler started
2022-04-26 16:19:05 log.py[line:230] WARNING Bad Request: /login
2022-04-26 16:20:36 autoreload.py[line:236] INFO /Users/wuhongbin/Desktop/养乐多/lwjTest/utils/aesPassword.py changed, reloading.
2022-04-26 16:20:39 base.py[line:166] INFO Scheduler started
2022-04-26 16:20:49 log.py[line:230] WARNING Bad Request: /register
2022-04-26 16:21:06 log.py[line:230] WARNING Bad Request: /login
2022-04-26 16:21:14 log.py[line:230] WARNING Bad Request: /login
2022-04-26 16:23:53 log.py[line:230] WARNING Bad Request: /login
2022-04-26 16:23:57 log.py[line:230] WARNING Bad Request: /login
2022-04-26 16:25:11 autoreload.py[line:236] INFO /Users/wuhongbin/Desktop/养乐多/lwjTest/utils/aesPassword.py changed, reloading.
2022-04-26 16:25:15 base.py[line:166] INFO Scheduler started
2022-04-26 16:25:21 autoreload.py[line:236] INFO /Users/wuhongbin/Desktop/养乐多/lwjTest/utils/aesPassword.py changed, reloading.
2022-04-26 16:25:24 base.py[line:166] INFO Scheduler started
2022-04-26 16:25:36 log.py[line:230] WARNING Bad Request: /login
2022-04-26 16:25:39 log.py[line:230] WARNING Method Not Allowed: /login
2022-04-26 16:25:58 log.py[line:230] WARNING Bad Request: /login
2022-04-26 16:26:22 log.py[line:230] WARNING Bad Request: /login
2022-04-26 16:26:44 log.py[line:230] WARNING Bad Request: /login
2022-04-26 16:26:52 log.py[line:230] WARNING Bad Request: /login
2022-04-26 16:26:54 log.py[line:230] WARNING Bad Request: /login
2022-04-26 16:27:04 log.py[line:230] WARNING Bad Request: /login
2022-04-26 16:29:43 autoreload.py[line:236] INFO /Users/wuhongbin/Desktop/养乐多/lwjTest/utils/aesPassword.py changed, reloading.
2022-04-26 16:29:45 base.py[line:166] INFO Scheduler started
2022-04-26 16:30:17 log.py[line:230] WARNING Bad Request: /login
2022-04-26 16:30:19 log.py[line:230] WARNING Bad Request: /login
2022-04-26 16:34:10 autoreload.py[line:236] INFO /Users/wuhongbin/Desktop/养乐多/lwjTest/utils/aesPassword.py changed, reloading.
2022-04-26 16:34:12 base.py[line:166] INFO Scheduler started
2022-04-26 16:35:20 log.py[line:230] WARNING Bad Request: /login
2022-04-26 16:37:53 base.py[line:166] INFO Scheduler started
2022-04-26 16:37:57 log.py[line:230] WARNING Bad Request: /login
2022-04-26 16:38:32 base.py[line:166] INFO Scheduler started
2022-04-26 16:38:34 log.py[line:230] WARNING Bad Request: /login
2022-04-26 16:39:27 autoreload.py[line:236] INFO /Users/wuhongbin/Desktop/养乐多/lwjTest/utils/aesPassword.py changed, reloading.
2022-04-26 16:39:29 base.py[line:166] INFO Scheduler started
2022-04-26 16:41:06 autoreload.py[line:236] INFO /Users/wuhongbin/Desktop/养乐多/lwjTest/utils/aesPassword.py changed, reloading.
2022-04-26 16:41:08 base.py[line:166] INFO Scheduler started
2022-04-26 16:42:28 autoreload.py[line:236] INFO /Users/wuhongbin/Desktop/养乐多/lwjTest/utils/aesPassword.py changed, reloading.
2022-04-26 16:42:30 base.py[line:166] INFO Scheduler started
2022-04-26 16:44:58 base.py[line:166] INFO Scheduler started
2022-04-26 16:45:20 log.py[line:230] WARNING Bad Request: /register
2022-04-26 16:45:46 autoreload.py[line:236] INFO /Users/wuhongbin/Desktop/养乐多/lwjTest/apps/users/utils.py changed, reloading.
2022-04-26 16:45:49 base.py[line:166] INFO Scheduler started
2022-04-26 16:46:10 log.py[line:230] WARNING Forbidden: /api/project/
2022-04-26 16:46:24 log.py[line:230] WARNING Bad Request: /jurisdiction/13683450131
2022-04-26 16:46:26 log.py[line:230] WARNING Method Not Allowed: /jurisdiction/13683450131
2022-04-26 16:47:51 base.py[line:166] INFO Scheduler started
2022-04-26 16:48:02 log.py[line:230] WARNING Forbidden: /jurisdiction/13683450133
2022-04-26 16:48:03 log.py[line:230] WARNING Forbidden: /jurisdiction/13683450133
2022-04-26 16:48:13 base.py[line:166] INFO Scheduler started
2022-04-26 16:51:33 log.py[line:230] ERROR Internal Server Error: /case/run/1/
Traceback (most recent call last):
  File "/Library/Frameworks/Python.framework/Versions/3.6/lib/python3.6/site-packages/django/db/backends/utils.py", line 84, in _execute
    return self.cursor.execute(sql, params)
  File "/Library/Frameworks/Python.framework/Versions/3.6/lib/python3.6/site-packages/django/db/backends/mysql/base.py", line 73, in execute
    return self.cursor.execute(query, args)
  File "/Library/Frameworks/Python.framework/Versions/3.6/lib/python3.6/site-packages/pymysql/cursors.py", line 170, in execute
    result = self._query(query)
  File "/Library/Frameworks/Python.framework/Versions/3.6/lib/python3.6/site-packages/pymysql/cursors.py", line 328, in _query
    conn.query(q)
  File "/Library/Frameworks/Python.framework/Versions/3.6/lib/python3.6/site-packages/pymysql/connections.py", line 517, in query
    self._affected_rows = self._read_query_result(unbuffered=unbuffered)
  File "/Library/Frameworks/Python.framework/Versions/3.6/lib/python3.6/site-packages/pymysql/connections.py", line 732, in _read_query_result
    result.read()
  File "/Library/Frameworks/Python.framework/Versions/3.6/lib/python3.6/site-packages/pymysql/connections.py", line 1075, in read
    first_packet = self.connection._read_packet()
  File "/Library/Frameworks/Python.framework/Versions/3.6/lib/python3.6/site-packages/pymysql/connections.py", line 684, in _read_packet
    packet.check_error()
  File "/Library/Frameworks/Python.framework/Versions/3.6/lib/python3.6/site-packages/pymysql/protocol.py", line 220, in check_error
    err.raise_mysql_exception(self._data)
  File "/Library/Frameworks/Python.framework/Versions/3.6/lib/python3.6/site-packages/pymysql/err.py", line 109, in raise_mysql_exception
    raise errorclass(errno, errval)
pymysql.err.DataError: (1406, "Data too long for column 'report_details' at row 1")

The above exception was the direct cause of the following exception:

Traceback (most recent call last):
  File "/Library/Frameworks/Python.framework/Versions/3.6/lib/python3.6/site-packages/django/core/handlers/exception.py", line 47, in inner
    response = get_response(request)
  File "/Library/Frameworks/Python.framework/Versions/3.6/lib/python3.6/site-packages/django/core/handlers/base.py", line 179, in _get_response
    response = wrapped_callback(request, *callback_args, **callback_kwargs)
  File "/Library/Frameworks/Python.framework/Versions/3.6/lib/python3.6/site-packages/django/views/decorators/csrf.py", line 54, in wrapped_view
    return view_func(*args, **kwargs)
  File "/Library/Frameworks/Python.framework/Versions/3.6/lib/python3.6/site-packages/django/views/generic/base.py", line 70, in view
    return self.dispatch(request, *args, **kwargs)
  File "/Library/Frameworks/Python.framework/Versions/3.6/lib/python3.6/site-packages/rest_framework/views.py", line 521, in dispatch
    response = self.handle_exception(exc)
  File "/Library/Frameworks/Python.framework/Versions/3.6/lib/python3.6/site-packages/rest_framework/views.py", line 477, in handle_exception
    self.raise_uncaught_exception(exc)
  File "/Library/Frameworks/Python.framework/Versions/3.6/lib/python3.6/site-packages/rest_framework/views.py", line 488, in raise_uncaught_exception
    raise exc
  File "/Library/Frameworks/Python.framework/Versions/3.6/lib/python3.6/site-packages/rest_framework/views.py", line 518, in dispatch
    response = handler(request, *args, **kwargs)
  File "/Users/wuhongbin/Desktop/养乐多/lwjTest/apps/case/views.py", line 45, in post
    run_case(case_id)
  File "/Users/wuhongbin/Desktop/养乐多/lwjTest/apps/case/run_case.py", line 171, in run_case
    report_details=report_data['report_details']
  File "/Library/Frameworks/Python.framework/Versions/3.6/lib/python3.6/site-packages/django/db/models/manager.py", line 85, in manager_method
    return getattr(self.get_queryset(), name)(*args, **kwargs)
  File "/Library/Frameworks/Python.framework/Versions/3.6/lib/python3.6/site-packages/django/db/models/query.py", line 447, in create
    obj.save(force_insert=True, using=self.db)
  File "/Library/Frameworks/Python.framework/Versions/3.6/lib/python3.6/site-packages/django/db/models/base.py", line 754, in save
    force_update=force_update, update_fields=update_fields)
  File "/Library/Frameworks/Python.framework/Versions/3.6/lib/python3.6/site-packages/django/db/models/base.py", line 792, in save_base
    force_update, using, update_fields,
  File "/Library/Frameworks/Python.framework/Versions/3.6/lib/python3.6/site-packages/django/db/models/base.py", line 895, in _save_table
    results = self._do_insert(cls._base_manager, using, fields, returning_fields, raw)
  File "/Library/Frameworks/Python.framework/Versions/3.6/lib/python3.6/site-packages/django/db/models/base.py", line 935, in _do_insert
    using=using, raw=raw,
  File "/Library/Frameworks/Python.framework/Versions/3.6/lib/python3.6/site-packages/django/db/models/manager.py", line 85, in manager_method
    return getattr(self.get_queryset(), name)(*args, **kwargs)
  File "/Library/Frameworks/Python.framework/Versions/3.6/lib/python3.6/site-packages/django/db/models/query.py", line 1254, in _insert
    return query.get_compiler(using=using).execute_sql(returning_fields)
  File "/Library/Frameworks/Python.framework/Versions/3.6/lib/python3.6/site-packages/django/db/models/sql/compiler.py", line 1397, in execute_sql
    cursor.execute(sql, params)
  File "/Library/Frameworks/Python.framework/Versions/3.6/lib/python3.6/site-packages/django/db/backends/utils.py", line 98, in execute
    return super().execute(sql, params)
  File "/Library/Frameworks/Python.framework/Versions/3.6/lib/python3.6/site-packages/django/db/backends/utils.py", line 66, in execute
    return self._execute_with_wrappers(sql, params, many=False, executor=self._execute)
  File "/Library/Frameworks/Python.framework/Versions/3.6/lib/python3.6/site-packages/django/db/backends/utils.py", line 75, in _execute_with_wrappers
    return executor(sql, params, many, context)
  File "/Library/Frameworks/Python.framework/Versions/3.6/lib/python3.6/site-packages/django/db/backends/utils.py", line 84, in _execute
    return self.cursor.execute(sql, params)
  File "/Library/Frameworks/Python.framework/Versions/3.6/lib/python3.6/site-packages/django/db/utils.py", line 90, in __exit__
    raise dj_exc_value.with_traceback(traceback) from exc_value
  File "/Library/Frameworks/Python.framework/Versions/3.6/lib/python3.6/site-packages/django/db/backends/utils.py", line 84, in _execute
    return self.cursor.execute(sql, params)
  File "/Library/Frameworks/Python.framework/Versions/3.6/lib/python3.6/site-packages/django/db/backends/mysql/base.py", line 73, in execute
    return self.cursor.execute(query, args)
  File "/Library/Frameworks/Python.framework/Versions/3.6/lib/python3.6/site-packages/pymysql/cursors.py", line 170, in execute
    result = self._query(query)
  File "/Library/Frameworks/Python.framework/Versions/3.6/lib/python3.6/site-packages/pymysql/cursors.py", line 328, in _query
    conn.query(q)
  File "/Library/Frameworks/Python.framework/Versions/3.6/lib/python3.6/site-packages/pymysql/connections.py", line 517, in query
    self._affected_rows = self._read_query_result(unbuffered=unbuffered)
  File "/Library/Frameworks/Python.framework/Versions/3.6/lib/python3.6/site-packages/pymysql/connections.py", line 732, in _read_query_result
    result.read()
  File "/Library/Frameworks/Python.framework/Versions/3.6/lib/python3.6/site-packages/pymysql/connections.py", line 1075, in read
    first_packet = self.connection._read_packet()
  File "/Library/Frameworks/Python.framework/Versions/3.6/lib/python3.6/site-packages/pymysql/connections.py", line 684, in _read_packet
    packet.check_error()
  File "/Library/Frameworks/Python.framework/Versions/3.6/lib/python3.6/site-packages/pymysql/protocol.py", line 220, in check_error
    err.raise_mysql_exception(self._data)
  File "/Library/Frameworks/Python.framework/Versions/3.6/lib/python3.6/site-packages/pymysql/err.py", line 109, in raise_mysql_exception
    raise errorclass(errno, errval)
django.db.utils.DataError: (1406, "Data too long for column 'report_details' at row 1")
2022-04-26 16:51:55 log.py[line:230] ERROR Internal Server Error: /case/run/1/
Traceback (most recent call last):
  File "/Library/Frameworks/Python.framework/Versions/3.6/lib/python3.6/site-packages/django/db/backends/utils.py", line 84, in _execute
    return self.cursor.execute(sql, params)
  File "/Library/Frameworks/Python.framework/Versions/3.6/lib/python3.6/site-packages/django/db/backends/mysql/base.py", line 73, in execute
    return self.cursor.execute(query, args)
  File "/Library/Frameworks/Python.framework/Versions/3.6/lib/python3.6/site-packages/pymysql/cursors.py", line 170, in execute
    result = self._query(query)
  File "/Library/Frameworks/Python.framework/Versions/3.6/lib/python3.6/site-packages/pymysql/cursors.py", line 328, in _query
    conn.query(q)
  File "/Library/Frameworks/Python.framework/Versions/3.6/lib/python3.6/site-packages/pymysql/connections.py", line 517, in query
    self._affected_rows = self._read_query_result(unbuffered=unbuffered)
  File "/Library/Frameworks/Python.framework/Versions/3.6/lib/python3.6/site-packages/pymysql/connections.py", line 732, in _read_query_result
    result.read()
  File "/Library/Frameworks/Python.framework/Versions/3.6/lib/python3.6/site-packages/pymysql/connections.py", line 1075, in read
    first_packet = self.connection._read_packet()
  File "/Library/Frameworks/Python.framework/Versions/3.6/lib/python3.6/site-packages/pymysql/connections.py", line 684, in _read_packet
    packet.check_error()
  File "/Library/Frameworks/Python.framework/Versions/3.6/lib/python3.6/site-packages/pymysql/protocol.py", line 220, in check_error
    err.raise_mysql_exception(self._data)
  File "/Library/Frameworks/Python.framework/Versions/3.6/lib/python3.6/site-packages/pymysql/err.py", line 109, in raise_mysql_exception
    raise errorclass(errno, errval)
pymysql.err.DataError: (1406, "Data too long for column 'report_details' at row 1")

The above exception was the direct cause of the following exception:

Traceback (most recent call last):
  File "/Library/Frameworks/Python.framework/Versions/3.6/lib/python3.6/site-packages/django/core/handlers/exception.py", line 47, in inner
    response = get_response(request)
  File "/Library/Frameworks/Python.framework/Versions/3.6/lib/python3.6/site-packages/django/core/handlers/base.py", line 179, in _get_response
    response = wrapped_callback(request, *callback_args, **callback_kwargs)
  File "/Library/Frameworks/Python.framework/Versions/3.6/lib/python3.6/site-packages/django/views/decorators/csrf.py", line 54, in wrapped_view
    return view_func(*args, **kwargs)
  File "/Library/Frameworks/Python.framework/Versions/3.6/lib/python3.6/site-packages/django/views/generic/base.py", line 70, in view
    return self.dispatch(request, *args, **kwargs)
  File "/Library/Frameworks/Python.framework/Versions/3.6/lib/python3.6/site-packages/rest_framework/views.py", line 521, in dispatch
    response = self.handle_exception(exc)
  File "/Library/Frameworks/Python.framework/Versions/3.6/lib/python3.6/site-packages/rest_framework/views.py", line 477, in handle_exception
    self.raise_uncaught_exception(exc)
  File "/Library/Frameworks/Python.framework/Versions/3.6/lib/python3.6/site-packages/rest_framework/views.py", line 488, in raise_uncaught_exception
    raise exc
  File "/Library/Frameworks/Python.framework/Versions/3.6/lib/python3.6/site-packages/rest_framework/views.py", line 518, in dispatch
    response = handler(request, *args, **kwargs)
  File "/Users/wuhongbin/Desktop/养乐多/lwjTest/apps/case/views.py", line 45, in post
    run_case(case_id)
  File "/Users/wuhongbin/Desktop/养乐多/lwjTest/apps/case/run_case.py", line 171, in run_case
    report_details=report_data['report_details']
  File "/Library/Frameworks/Python.framework/Versions/3.6/lib/python3.6/site-packages/django/db/models/manager.py", line 85, in manager_method
    return getattr(self.get_queryset(), name)(*args, **kwargs)
  File "/Library/Frameworks/Python.framework/Versions/3.6/lib/python3.6/site-packages/django/db/models/query.py", line 447, in create
    obj.save(force_insert=True, using=self.db)
  File "/Library/Frameworks/Python.framework/Versions/3.6/lib/python3.6/site-packages/django/db/models/base.py", line 754, in save
    force_update=force_update, update_fields=update_fields)
  File "/Library/Frameworks/Python.framework/Versions/3.6/lib/python3.6/site-packages/django/db/models/base.py", line 792, in save_base
    force_update, using, update_fields,
  File "/Library/Frameworks/Python.framework/Versions/3.6/lib/python3.6/site-packages/django/db/models/base.py", line 895, in _save_table
    results = self._do_insert(cls._base_manager, using, fields, returning_fields, raw)
  File "/Library/Frameworks/Python.framework/Versions/3.6/lib/python3.6/site-packages/django/db/models/base.py", line 935, in _do_insert
    using=using, raw=raw,
  File "/Library/Frameworks/Python.framework/Versions/3.6/lib/python3.6/site-packages/django/db/models/manager.py", line 85, in manager_method
    return getattr(self.get_queryset(), name)(*args, **kwargs)
  File "/Library/Frameworks/Python.framework/Versions/3.6/lib/python3.6/site-packages/django/db/models/query.py", line 1254, in _insert
    return query.get_compiler(using=using).execute_sql(returning_fields)
  File "/Library/Frameworks/Python.framework/Versions/3.6/lib/python3.6/site-packages/django/db/models/sql/compiler.py", line 1397, in execute_sql
    cursor.execute(sql, params)
  File "/Library/Frameworks/Python.framework/Versions/3.6/lib/python3.6/site-packages/django/db/backends/utils.py", line 98, in execute
    return super().execute(sql, params)
  File "/Library/Frameworks/Python.framework/Versions/3.6/lib/python3.6/site-packages/django/db/backends/utils.py", line 66, in execute
    return self._execute_with_wrappers(sql, params, many=False, executor=self._execute)
  File "/Library/Frameworks/Python.framework/Versions/3.6/lib/python3.6/site-packages/django/db/backends/utils.py", line 75, in _execute_with_wrappers
    return executor(sql, params, many, context)
  File "/Library/Frameworks/Python.framework/Versions/3.6/lib/python3.6/site-packages/django/db/backends/utils.py", line 84, in _execute
    return self.cursor.execute(sql, params)
  File "/Library/Frameworks/Python.framework/Versions/3.6/lib/python3.6/site-packages/django/db/utils.py", line 90, in __exit__
    raise dj_exc_value.with_traceback(traceback) from exc_value
  File "/Library/Frameworks/Python.framework/Versions/3.6/lib/python3.6/site-packages/django/db/backends/utils.py", line 84, in _execute
    return self.cursor.execute(sql, params)
  File "/Library/Frameworks/Python.framework/Versions/3.6/lib/python3.6/site-packages/django/db/backends/mysql/base.py", line 73, in execute
    return self.cursor.execute(query, args)
  File "/Library/Frameworks/Python.framework/Versions/3.6/lib/python3.6/site-packages/pymysql/cursors.py", line 170, in execute
    result = self._query(query)
  File "/Library/Frameworks/Python.framework/Versions/3.6/lib/python3.6/site-packages/pymysql/cursors.py", line 328, in _query
    conn.query(q)
  File "/Library/Frameworks/Python.framework/Versions/3.6/lib/python3.6/site-packages/pymysql/connections.py", line 517, in query
    self._affected_rows = self._read_query_result(unbuffered=unbuffered)
  File "/Library/Frameworks/Python.framework/Versions/3.6/lib/python3.6/site-packages/pymysql/connections.py", line 732, in _read_query_result
    result.read()
  File "/Library/Frameworks/Python.framework/Versions/3.6/lib/python3.6/site-packages/pymysql/connections.py", line 1075, in read
    first_packet = self.connection._read_packet()
  File "/Library/Frameworks/Python.framework/Versions/3.6/lib/python3.6/site-packages/pymysql/connections.py", line 684, in _read_packet
    packet.check_error()
  File "/Library/Frameworks/Python.framework/Versions/3.6/lib/python3.6/site-packages/pymysql/protocol.py", line 220, in check_error
    err.raise_mysql_exception(self._data)
  File "/Library/Frameworks/Python.framework/Versions/3.6/lib/python3.6/site-packages/pymysql/err.py", line 109, in raise_mysql_exception
    raise errorclass(errno, errval)
django.db.utils.DataError: (1406, "Data too long for column 'report_details' at row 1")
2022-04-26 16:53:11 autoreload.py[line:236] INFO /Users/wuhongbin/Desktop/养乐多/lwjTest/apps/report/models.py changed, reloading.
2022-04-26 16:53:13 base.py[line:166] INFO Scheduler started
2022-04-26 16:53:17 base.py[line:166] INFO Scheduler started
2022-04-26 16:53:21 base.py[line:166] INFO Scheduler started
2022-04-26 16:54:50 base.py[line:166] INFO Scheduler started
2022-04-26 16:56:12 base.py[line:166] INFO Scheduler started
2022-04-26 16:57:30 base.py[line:166] INFO Scheduler started
2022-05-07 11:14:18 base.py[line:166] INFO Scheduler started
2022-05-07 11:15:57 autoreload.py[line:236] INFO /Users/wuhongbin/Desktop/养乐多/lwjTest/apps/report/views.py changed, reloading.
2022-05-07 11:17:09 base.py[line:166] INFO Scheduler started
2022-05-07 11:18:41 log.py[line:230] WARNING Not Found: /report/lwj_http_report-2022-04-07-10-57-45.html
2022-05-07 11:18:41 log.py[line:230] WARNING Not Found: /favicon.ico
2022-05-07 11:18:46 log.py[line:230] WARNING Not Found: /report/lwj_http_report-2022-04-07-10-57-45
2022-05-07 11:18:53 log.py[line:230] WARNING Not Found: /lwj_http_report-2022-04-07-10-57-45
2022-05-07 11:19:01 log.py[line:230] WARNING Not Found: /report/lwj_http_report-2022-04-07-10-57-45
2022-05-07 11:19:09 log.py[line:230] ERROR Internal Server Error: /report/lwj_http_report-2022-04-07-10-57-45/
Traceback (most recent call last):
  File "/Library/Frameworks/Python.framework/Versions/3.6/lib/python3.6/site-packages/django/core/handlers/exception.py", line 47, in inner
    response = get_response(request)
  File "/Library/Frameworks/Python.framework/Versions/3.6/lib/python3.6/site-packages/django/core/handlers/base.py", line 179, in _get_response
    response = wrapped_callback(request, *callback_args, **callback_kwargs)
  File "/Users/wuhongbin/Desktop/养乐多/lwjTest/apps/report/views.py", line 43, in reportDetails
    return render(request,"report/{}".format(name))
  File "/Library/Frameworks/Python.framework/Versions/3.6/lib/python3.6/site-packages/django/shortcuts.py", line 19, in render
    content = loader.render_to_string(template_name, context, request, using=using)
  File "/Library/Frameworks/Python.framework/Versions/3.6/lib/python3.6/site-packages/django/template/loader.py", line 61, in render_to_string
    template = get_template(template_name, using=using)
  File "/Library/Frameworks/Python.framework/Versions/3.6/lib/python3.6/site-packages/django/template/loader.py", line 19, in get_template
    raise TemplateDoesNotExist(template_name, chain=chain)
django.template.exceptions.TemplateDoesNotExist: report/lwj_http_report-2022-04-07-10-57-45
2022-05-07 11:20:11 log.py[line:230] WARNING Not Found: /report/send/meail/lwj_http_report-2022-04-07-10-57-45.html/
2022-05-07 11:20:25 log.py[line:230] WARNING Not Found: /report/send/meail/lwj_http_report-2022-04-07-10-57-45/
2022-05-07 11:21:37 log.py[line:230] WARNING Not Found: /report/send/meail/lwj_http_report-2022-04-07-10-57-45.html/
2022-05-07 11:23:17 log.py[line:230] ERROR Internal Server Error: /report/send/meail/lwj_http_report-2022-04-07-10-57-45.html
Traceback (most recent call last):
  File "/Library/Frameworks/Python.framework/Versions/3.6/lib/python3.6/site-packages/django/core/handlers/exception.py", line 47, in inner
    response = get_response(request)
  File "/Library/Frameworks/Python.framework/Versions/3.6/lib/python3.6/site-packages/django/core/handlers/base.py", line 179, in _get_response
    response = wrapped_callback(request, *callback_args, **callback_kwargs)
  File "/Users/wuhongbin/Desktop/养乐多/lwjTest/apps/report/views.py", line 95, in mailReport
    "project_name":report.project_name,
AttributeError: 'NoneType' object has no attribute 'project_name'
2022-05-07 11:24:34 log.py[line:230] ERROR Internal Server Error: /report/send/meail/fusion_report-2022-04-26-16-57-40
Traceback (most recent call last):
  File "/Library/Frameworks/Python.framework/Versions/3.6/lib/python3.6/site-packages/django/core/handlers/exception.py", line 47, in inner
    response = get_response(request)
  File "/Library/Frameworks/Python.framework/Versions/3.6/lib/python3.6/site-packages/django/core/handlers/base.py", line 179, in _get_response
    response = wrapped_callback(request, *callback_args, **callback_kwargs)
  File "/Users/wuhongbin/Desktop/养乐多/lwjTest/apps/report/views.py", line 101, in mailReport
    if testMail():
  File "/Users/wuhongbin/Desktop/养乐多/lwjTest/apps/report/views.py", line 81, in testMail
    if msg.send():
  File "/Library/Frameworks/Python.framework/Versions/3.6/lib/python3.6/site-packages/django/core/mail/message.py", line 284, in send
    return self.get_connection(fail_silently).send_messages([self])
  File "/Library/Frameworks/Python.framework/Versions/3.6/lib/python3.6/site-packages/django/core/mail/backends/smtp.py", line 102, in send_messages
    new_conn_created = self.open()
  File "/Library/Frameworks/Python.framework/Versions/3.6/lib/python3.6/site-packages/django/core/mail/backends/smtp.py", line 69, in open
    self.connection.login(self.username, self.password)
  File "/Library/Frameworks/Python.framework/Versions/3.6/lib/python3.6/smtplib.py", line 730, in login
    raise last_exception
  File "/Library/Frameworks/Python.framework/Versions/3.6/lib/python3.6/smtplib.py", line 721, in login
    initial_response_ok=initial_response_ok)
  File "/Library/Frameworks/Python.framework/Versions/3.6/lib/python3.6/smtplib.py", line 642, in auth
    raise SMTPAuthenticationError(code, resp)
smtplib.SMTPAuthenticationError: (535, b'Error: authentication failed')
2022-05-07 11:24:51 log.py[line:230] ERROR Internal Server Error: /report/send/meail/fusion_report-2022-04-26-16-57-40
Traceback (most recent call last):
  File "/Library/Frameworks/Python.framework/Versions/3.6/lib/python3.6/site-packages/django/core/handlers/exception.py", line 47, in inner
    response = get_response(request)
  File "/Library/Frameworks/Python.framework/Versions/3.6/lib/python3.6/site-packages/django/core/handlers/base.py", line 179, in _get_response
    response = wrapped_callback(request, *callback_args, **callback_kwargs)
  File "/Users/wuhongbin/Desktop/养乐多/lwjTest/apps/report/views.py", line 101, in mailReport
    if testMail():
  File "/Users/wuhongbin/Desktop/养乐多/lwjTest/apps/report/views.py", line 81, in testMail
    if msg.send():
  File "/Library/Frameworks/Python.framework/Versions/3.6/lib/python3.6/site-packages/django/core/mail/message.py", line 284, in send
    return self.get_connection(fail_silently).send_messages([self])
  File "/Library/Frameworks/Python.framework/Versions/3.6/lib/python3.6/site-packages/django/core/mail/backends/smtp.py", line 102, in send_messages
    new_conn_created = self.open()
  File "/Library/Frameworks/Python.framework/Versions/3.6/lib/python3.6/site-packages/django/core/mail/backends/smtp.py", line 69, in open
    self.connection.login(self.username, self.password)
  File "/Library/Frameworks/Python.framework/Versions/3.6/lib/python3.6/smtplib.py", line 730, in login
    raise last_exception
  File "/Library/Frameworks/Python.framework/Versions/3.6/lib/python3.6/smtplib.py", line 721, in login
    initial_response_ok=initial_response_ok)
  File "/Library/Frameworks/Python.framework/Versions/3.6/lib/python3.6/smtplib.py", line 642, in auth
    raise SMTPAuthenticationError(code, resp)
smtplib.SMTPAuthenticationError: (535, b'Error: authentication failed')
2022-05-07 11:31:30 autoreload.py[line:236] INFO /Users/wuhongbin/Desktop/养乐多/lwjTest/apps/report/views.py changed, reloading.
2022-05-07 11:31:33 base.py[line:166] INFO Scheduler started
2022-05-07 11:32:02 autoreload.py[line:236] INFO /Users/wuhongbin/Desktop/养乐多/lwjTest/apps/report/views.py changed, reloading.
2022-05-07 11:32:05 base.py[line:166] INFO Scheduler started
2022-05-07 11:32:08 autoreload.py[line:236] INFO /Users/wuhongbin/Desktop/养乐多/lwjTest/apps/report/views.py changed, reloading.
2022-05-07 11:32:10 base.py[line:166] INFO Scheduler started
2022-05-07 11:32:16 autoreload.py[line:236] INFO /Users/wuhongbin/Desktop/养乐多/lwjTest/apps/report/views.py changed, reloading.
2022-05-07 11:32:18 base.py[line:166] INFO Scheduler started
2022-05-07 11:32:25 autoreload.py[line:236] INFO /Users/wuhongbin/Desktop/养乐多/lwjTest/apps/report/views.py changed, reloading.
2022-05-07 11:32:26 base.py[line:166] INFO Scheduler started
2022-05-07 11:32:32 autoreload.py[line:236] INFO /Users/wuhongbin/Desktop/养乐多/lwjTest/apps/report/views.py changed, reloading.
2022-05-07 11:32:47 base.py[line:166] INFO Scheduler started
2022-05-07 11:33:07 autoreload.py[line:236] INFO /Users/wuhongbin/Desktop/养乐多/lwjTest/apps/report/views.py changed, reloading.
2022-05-07 11:33:10 base.py[line:166] INFO Scheduler started
2022-05-07 11:33:21 autoreload.py[line:236] INFO /Users/wuhongbin/Desktop/养乐多/lwjTest/apps/report/views.py changed, reloading.
2022-05-07 11:33:22 base.py[line:166] INFO Scheduler started
2022-05-07 11:33:43 base.py[line:166] INFO Scheduler started
2022-05-07 11:33:50 log.py[line:230] ERROR Internal Server Error: /report/send/meail/fusion_report-2022-04-26-16-57-40
Traceback (most recent call last):
  File "/Library/Frameworks/Python.framework/Versions/3.6/lib/python3.6/site-packages/django/core/handlers/exception.py", line 47, in inner
    response = get_response(request)
  File "/Library/Frameworks/Python.framework/Versions/3.6/lib/python3.6/site-packages/django/core/handlers/base.py", line 179, in _get_response
    response = wrapped_callback(request, *callback_args, **callback_kwargs)
  File "/Users/wuhongbin/Desktop/养乐多/lwjTest/apps/report/views.py", line 93, in mailReport
    mail.send_mail(subject="测试邮件",message="内容",from_email='xiao_whb@163.com',recipient_list=['xiao_whb@163.com','wuhongbin@liweijia.com'])
  File "/Library/Frameworks/Python.framework/Versions/3.6/lib/python3.6/site-packages/django/core/mail/__init__.py", line 61, in send_mail
    return mail.send()
  File "/Library/Frameworks/Python.framework/Versions/3.6/lib/python3.6/site-packages/django/core/mail/message.py", line 284, in send
    return self.get_connection(fail_silently).send_messages([self])
  File "/Library/Frameworks/Python.framework/Versions/3.6/lib/python3.6/site-packages/django/core/mail/backends/smtp.py", line 102, in send_messages
    new_conn_created = self.open()
  File "/Library/Frameworks/Python.framework/Versions/3.6/lib/python3.6/site-packages/django/core/mail/backends/smtp.py", line 69, in open
    self.connection.login(self.username, self.password)
  File "/Library/Frameworks/Python.framework/Versions/3.6/lib/python3.6/smtplib.py", line 730, in login
    raise last_exception
  File "/Library/Frameworks/Python.framework/Versions/3.6/lib/python3.6/smtplib.py", line 721, in login
    initial_response_ok=initial_response_ok)
  File "/Library/Frameworks/Python.framework/Versions/3.6/lib/python3.6/smtplib.py", line 642, in auth
    raise SMTPAuthenticationError(code, resp)
smtplib.SMTPAuthenticationError: (535, b'Error: authentication failed')
2022-05-07 11:35:44 base.py[line:166] INFO Scheduler started
2022-05-07 11:35:50 log.py[line:230] ERROR Internal Server Error: /report/send/meail/fusion_report-2022-04-26-16-57-40
Traceback (most recent call last):
  File "/Library/Frameworks/Python.framework/Versions/3.6/lib/python3.6/site-packages/django/core/handlers/exception.py", line 47, in inner
    response = get_response(request)
  File "/Library/Frameworks/Python.framework/Versions/3.6/lib/python3.6/site-packages/django/core/handlers/base.py", line 202, in _get_response
    response = response.render()
  File "/Library/Frameworks/Python.framework/Versions/3.6/lib/python3.6/site-packages/django/template/response.py", line 105, in render
    self.content = self.rendered_content
  File "/Library/Frameworks/Python.framework/Versions/3.6/lib/python3.6/site-packages/rest_framework/response.py", line 55, in rendered_content
    assert renderer, ".accepted_renderer not set on Response"
AssertionError: .accepted_renderer not set on Response
2022-05-07 11:36:30 base.py[line:166] INFO Scheduler started
2022-05-07 11:36:33 log.py[line:230] ERROR Internal Server Error: /report/send/meail/fusion_report-2022-04-26-16-57-40
Traceback (most recent call last):
  File "/Library/Frameworks/Python.framework/Versions/3.6/lib/python3.6/site-packages/django/core/handlers/exception.py", line 47, in inner
    response = get_response(request)
  File "/Library/Frameworks/Python.framework/Versions/3.6/lib/python3.6/site-packages/django/core/handlers/base.py", line 179, in _get_response
    response = wrapped_callback(request, *callback_args, **callback_kwargs)
  File "/Users/wuhongbin/Desktop/养乐多/lwjTest/apps/report/views.py", line 94, in mailReport
    return render(request,template_name="report.html",context=context)
NameError: name 'context' is not defined
2022-05-07 11:37:03 base.py[line:166] INFO Scheduler started
2022-05-07 11:39:46 autoreload.py[line:236] INFO /Users/wuhongbin/Desktop/养乐多/lwjTest/apps/report/views.py changed, reloading.
2022-05-07 11:48:52 base.py[line:166] INFO Scheduler started
2022-05-07 13:54:13 autoreload.py[line:236] INFO /Users/wuhongbin/Desktop/养乐多/lwjTest/apps/report/views.py changed, reloading.
2022-05-07 13:54:16 base.py[line:166] INFO Scheduler started
2022-05-07 13:54:54 autoreload.py[line:236] INFO /Users/wuhongbin/Desktop/养乐多/lwjTest/apps/report/views.py changed, reloading.
2022-05-07 13:54:56 base.py[line:166] INFO Scheduler started
2022-05-07 13:55:01 base.py[line:166] INFO Scheduler started
2022-05-07 13:55:08 base.py[line:166] INFO Scheduler started
2022-05-07 13:56:47 base.py[line:166] INFO Scheduler started
2022-05-07 13:56:53 log.py[line:230] WARNING Not Found: /report/email
2022-05-07 13:56:55 log.py[line:230] ERROR Internal Server Error: /report/email/
Traceback (most recent call last):
  File "/Library/Frameworks/Python.framework/Versions/3.6/lib/python3.6/site-packages/django/core/handlers/exception.py", line 47, in inner
    response = get_response(request)
  File "/Library/Frameworks/Python.framework/Versions/3.6/lib/python3.6/site-packages/django/core/handlers/base.py", line 179, in _get_response
    response = wrapped_callback(request, *callback_args, **callback_kwargs)
  File "/Users/wuhongbin/Desktop/养乐多/lwjTest/apps/report/views.py", line 44, in reportDetails
    return render(request,"report/{}".format(name))
  File "/Library/Frameworks/Python.framework/Versions/3.6/lib/python3.6/site-packages/django/shortcuts.py", line 19, in render
    content = loader.render_to_string(template_name, context, request, using=using)
  File "/Library/Frameworks/Python.framework/Versions/3.6/lib/python3.6/site-packages/django/template/loader.py", line 61, in render_to_string
    template = get_template(template_name, using=using)
  File "/Library/Frameworks/Python.framework/Versions/3.6/lib/python3.6/site-packages/django/template/loader.py", line 19, in get_template
    raise TemplateDoesNotExist(template_name, chain=chain)
django.template.exceptions.TemplateDoesNotExist: report/email
2022-05-07 13:56:57 log.py[line:230] WARNING Not Found: /report/email
2022-05-07 13:57:02 log.py[line:230] WARNING Not Found: /report/email
2022-05-07 13:57:08 log.py[line:230] ERROR Internal Server Error: /report/email/
Traceback (most recent call last):
  File "/Library/Frameworks/Python.framework/Versions/3.6/lib/python3.6/site-packages/django/core/handlers/exception.py", line 47, in inner
    response = get_response(request)
  File "/Library/Frameworks/Python.framework/Versions/3.6/lib/python3.6/site-packages/django/core/handlers/base.py", line 179, in _get_response
    response = wrapped_callback(request, *callback_args, **callback_kwargs)
  File "/Users/wuhongbin/Desktop/养乐多/lwjTest/apps/report/views.py", line 44, in reportDetails
    return render(request,"report/{}".format(name))
  File "/Library/Frameworks/Python.framework/Versions/3.6/lib/python3.6/site-packages/django/shortcuts.py", line 19, in render
    content = loader.render_to_string(template_name, context, request, using=using)
  File "/Library/Frameworks/Python.framework/Versions/3.6/lib/python3.6/site-packages/django/template/loader.py", line 61, in render_to_string
    template = get_template(template_name, using=using)
  File "/Library/Frameworks/Python.framework/Versions/3.6/lib/python3.6/site-packages/django/template/loader.py", line 19, in get_template
    raise TemplateDoesNotExist(template_name, chain=chain)
django.template.exceptions.TemplateDoesNotExist: report/email
2022-05-07 13:58:02 base.py[line:166] INFO Scheduler started
2022-05-07 13:58:06 log.py[line:230] ERROR Internal Server Error: /report/email/
Traceback (most recent call last):
  File "/Library/Frameworks/Python.framework/Versions/3.6/lib/python3.6/site-packages/django/core/handlers/exception.py", line 47, in inner
    response = get_response(request)
  File "/Library/Frameworks/Python.framework/Versions/3.6/lib/python3.6/site-packages/django/core/handlers/base.py", line 179, in _get_response
    response = wrapped_callback(request, *callback_args, **callback_kwargs)
  File "/Users/wuhongbin/Desktop/养乐多/lwjTest/apps/report/views.py", line 44, in reportDetails
    return render(request,"report/{}".format(name))
  File "/Library/Frameworks/Python.framework/Versions/3.6/lib/python3.6/site-packages/django/shortcuts.py", line 19, in render
    content = loader.render_to_string(template_name, context, request, using=using)
  File "/Library/Frameworks/Python.framework/Versions/3.6/lib/python3.6/site-packages/django/template/loader.py", line 61, in render_to_string
    template = get_template(template_name, using=using)
  File "/Library/Frameworks/Python.framework/Versions/3.6/lib/python3.6/site-packages/django/template/loader.py", line 19, in get_template
    raise TemplateDoesNotExist(template_name, chain=chain)
django.template.exceptions.TemplateDoesNotExist: report/email
2022-05-07 13:59:45 autoreload.py[line:236] INFO /Users/wuhongbin/Desktop/养乐多/lwjTest/lwjTest/settings.py changed, reloading.
2022-05-07 13:59:47 base.py[line:166] INFO Scheduler started
2022-05-07 14:00:55 base.py[line:166] INFO Scheduler started
2022-05-07 14:01:04 base.py[line:166] INFO Scheduler started
2022-05-07 14:01:16 log.py[line:230] WARNING Forbidden: /api/api/
2022-05-07 14:01:27 log.py[line:230] WARNING Forbidden: /api/project/
2022-05-07 14:11:27 log.py[line:230] ERROR Internal Server Error: /report/email/
Traceback (most recent call last):
  File "/Library/Frameworks/Python.framework/Versions/3.6/lib/python3.6/site-packages/django/core/handlers/exception.py", line 47, in inner
    response = get_response(request)
  File "/Library/Frameworks/Python.framework/Versions/3.6/lib/python3.6/site-packages/django/core/handlers/base.py", line 179, in _get_response
    response = wrapped_callback(request, *callback_args, **callback_kwargs)
  File "/Users/wuhongbin/Desktop/养乐多/lwjTest/apps/report/views.py", line 44, in reportDetails
    return render(request,"report/{}".format(name))
  File "/Library/Frameworks/Python.framework/Versions/3.6/lib/python3.6/site-packages/django/shortcuts.py", line 19, in render
    content = loader.render_to_string(template_name, context, request, using=using)
  File "/Library/Frameworks/Python.framework/Versions/3.6/lib/python3.6/site-packages/django/template/loader.py", line 61, in render_to_string
    template = get_template(template_name, using=using)
  File "/Library/Frameworks/Python.framework/Versions/3.6/lib/python3.6/site-packages/django/template/loader.py", line 19, in get_template
    raise TemplateDoesNotExist(template_name, chain=chain)
django.template.exceptions.TemplateDoesNotExist: report/email
2022-05-07 14:11:59 base.py[line:166] INFO Scheduler started
2022-05-07 14:12:00 log.py[line:230] ERROR Internal Server Error: /report/emails/
Traceback (most recent call last):
  File "/Library/Frameworks/Python.framework/Versions/3.6/lib/python3.6/site-packages/django/core/handlers/exception.py", line 47, in inner
    response = get_response(request)
  File "/Library/Frameworks/Python.framework/Versions/3.6/lib/python3.6/site-packages/django/core/handlers/base.py", line 179, in _get_response
    response = wrapped_callback(request, *callback_args, **callback_kwargs)
  File "/Users/wuhongbin/Desktop/养乐多/lwjTest/apps/report/views.py", line 44, in reportDetails
    return render(request,"report/{}".format(name))
  File "/Library/Frameworks/Python.framework/Versions/3.6/lib/python3.6/site-packages/django/shortcuts.py", line 19, in render
    content = loader.render_to_string(template_name, context, request, using=using)
  File "/Library/Frameworks/Python.framework/Versions/3.6/lib/python3.6/site-packages/django/template/loader.py", line 61, in render_to_string
    template = get_template(template_name, using=using)
  File "/Library/Frameworks/Python.framework/Versions/3.6/lib/python3.6/site-packages/django/template/loader.py", line 19, in get_template
    raise TemplateDoesNotExist(template_name, chain=chain)
django.template.exceptions.TemplateDoesNotExist: report/emails
2022-05-07 14:12:01 log.py[line:230] ERROR Internal Server Error: /report/emails/
Traceback (most recent call last):
  File "/Library/Frameworks/Python.framework/Versions/3.6/lib/python3.6/site-packages/django/core/handlers/exception.py", line 47, in inner
    response = get_response(request)
  File "/Library/Frameworks/Python.framework/Versions/3.6/lib/python3.6/site-packages/django/core/handlers/base.py", line 179, in _get_response
    response = wrapped_callback(request, *callback_args, **callback_kwargs)
  File "/Users/wuhongbin/Desktop/养乐多/lwjTest/apps/report/views.py", line 44, in reportDetails
    return render(request,"report/{}".format(name))
  File "/Library/Frameworks/Python.framework/Versions/3.6/lib/python3.6/site-packages/django/shortcuts.py", line 19, in render
    content = loader.render_to_string(template_name, context, request, using=using)
  File "/Library/Frameworks/Python.framework/Versions/3.6/lib/python3.6/site-packages/django/template/loader.py", line 61, in render_to_string
    template = get_template(template_name, using=using)
  File "/Library/Frameworks/Python.framework/Versions/3.6/lib/python3.6/site-packages/django/template/loader.py", line 19, in get_template
    raise TemplateDoesNotExist(template_name, chain=chain)
django.template.exceptions.TemplateDoesNotExist: report/emails
2022-05-07 14:13:20 autoreload.py[line:236] INFO /Users/wuhongbin/Desktop/养乐多/lwjTest/apps/apiTest/serializers.py changed, reloading.
2022-05-07 14:13:23 base.py[line:166] INFO Scheduler started
2022-05-07 14:15:02 base.py[line:166] INFO Scheduler started
2022-05-07 14:15:04 log.py[line:230] WARNING Not Found: /report/emails/
2022-05-07 14:15:11 autoreload.py[line:236] INFO /Users/wuhongbin/Desktop/养乐多/lwjTest/apps/report/urls.py changed, reloading.
2022-05-07 14:15:12 base.py[line:166] INFO Scheduler started
2022-05-07 14:15:14 log.py[line:230] WARNING Not Found: /report/email/
2022-05-07 14:15:46 log.py[line:230] WARNING Not Found: /report/email/
2022-05-07 14:16:04 log.py[line:230] WARNING Not Found: /report/email/
2022-05-07 14:16:14 log.py[line:230] WARNING Forbidden: /report/list/
2022-05-07 14:16:28 base.py[line:166] INFO Scheduler started
2022-05-07 14:16:37 log.py[line:230] WARNING Not Found: /report/email/
2022-05-07 14:18:13 base.py[line:166] INFO Scheduler started
2022-05-07 14:18:16 log.py[line:230] ERROR Internal Server Error: /report/email/
Traceback (most recent call last):
  File "/Library/Frameworks/Python.framework/Versions/3.6/lib/python3.6/site-packages/django/core/handlers/exception.py", line 47, in inner
    response = get_response(request)
  File "/Library/Frameworks/Python.framework/Versions/3.6/lib/python3.6/site-packages/django/core/handlers/base.py", line 179, in _get_response
    response = wrapped_callback(request, *callback_args, **callback_kwargs)
  File "/Users/wuhongbin/Desktop/养乐多/lwjTest/apps/report/views.py", line 50, in reportDetails
    return render(request,"report/{}".format(name))
  File "/Library/Frameworks/Python.framework/Versions/3.6/lib/python3.6/site-packages/django/shortcuts.py", line 19, in render
    content = loader.render_to_string(template_name, context, request, using=using)
  File "/Library/Frameworks/Python.framework/Versions/3.6/lib/python3.6/site-packages/django/template/loader.py", line 61, in render_to_string
    template = get_template(template_name, using=using)
  File "/Library/Frameworks/Python.framework/Versions/3.6/lib/python3.6/site-packages/django/template/loader.py", line 19, in get_template
    raise TemplateDoesNotExist(template_name, chain=chain)
django.template.exceptions.TemplateDoesNotExist: report/email
2022-05-07 14:18:24 base.py[line:166] INFO Scheduler started
2022-05-07 14:18:26 log.py[line:230] WARNING Not Found: /report/email/
2022-05-07 14:19:26 base.py[line:166] INFO Scheduler started
2022-05-07 14:19:28 log.py[line:230] WARNING Not Found: /report/email/
2022-05-07 14:19:31 log.py[line:230] WARNING Not Found: /report/email/
2022-05-07 14:20:31 autoreload.py[line:236] INFO /Users/wuhongbin/Desktop/养乐多/lwjTest/apps/report/views.py changed, reloading.
2022-05-07 14:20:33 base.py[line:166] INFO Scheduler started
2022-05-07 14:20:33 base.py[line:166] INFO Scheduler started
2022-05-07 14:20:41 base.py[line:166] INFO Scheduler started
2022-05-07 14:20:55 log.py[line:230] WARNING Not Found: /report/email/
2022-05-07 14:21:12 base.py[line:166] INFO Scheduler started
2022-05-07 14:21:14 log.py[line:230] WARNING Not Found: /report/aaaa/
2022-05-07 14:21:53 base.py[line:166] INFO Scheduler started
2022-05-07 14:22:03 base.py[line:166] INFO Scheduler started
2022-05-07 14:22:04 log.py[line:230] ERROR Internal Server Error: /report/email/
Traceback (most recent call last):
  File "/Library/Frameworks/Python.framework/Versions/3.6/lib/python3.6/site-packages/django/core/handlers/exception.py", line 47, in inner
    response = get_response(request)
  File "/Library/Frameworks/Python.framework/Versions/3.6/lib/python3.6/site-packages/django/core/handlers/base.py", line 179, in _get_response
    response = wrapped_callback(request, *callback_args, **callback_kwargs)
  File "/Users/wuhongbin/Desktop/养乐多/lwjTest/apps/report/views.py", line 50, in reportDetails
    return render(request,"report/{}".format(name))
  File "/Library/Frameworks/Python.framework/Versions/3.6/lib/python3.6/site-packages/django/shortcuts.py", line 19, in render
    content = loader.render_to_string(template_name, context, request, using=using)
  File "/Library/Frameworks/Python.framework/Versions/3.6/lib/python3.6/site-packages/django/template/loader.py", line 61, in render_to_string
    template = get_template(template_name, using=using)
  File "/Library/Frameworks/Python.framework/Versions/3.6/lib/python3.6/site-packages/django/template/loader.py", line 19, in get_template
    raise TemplateDoesNotExist(template_name, chain=chain)
django.template.exceptions.TemplateDoesNotExist: report/email
2022-05-07 14:22:05 log.py[line:230] ERROR Internal Server Error: /report/email/
Traceback (most recent call last):
  File "/Library/Frameworks/Python.framework/Versions/3.6/lib/python3.6/site-packages/django/core/handlers/exception.py", line 47, in inner
    response = get_response(request)
  File "/Library/Frameworks/Python.framework/Versions/3.6/lib/python3.6/site-packages/django/core/handlers/base.py", line 179, in _get_response
    response = wrapped_callback(request, *callback_args, **callback_kwargs)
  File "/Users/wuhongbin/Desktop/养乐多/lwjTest/apps/report/views.py", line 50, in reportDetails
    return render(request,"report/{}".format(name))
  File "/Library/Frameworks/Python.framework/Versions/3.6/lib/python3.6/site-packages/django/shortcuts.py", line 19, in render
    content = loader.render_to_string(template_name, context, request, using=using)
  File "/Library/Frameworks/Python.framework/Versions/3.6/lib/python3.6/site-packages/django/template/loader.py", line 61, in render_to_string
    template = get_template(template_name, using=using)
  File "/Library/Frameworks/Python.framework/Versions/3.6/lib/python3.6/site-packages/django/template/loader.py", line 19, in get_template
    raise TemplateDoesNotExist(template_name, chain=chain)
django.template.exceptions.TemplateDoesNotExist: report/email
2022-05-07 14:30:42 log.py[line:230] ERROR Internal Server Error: /report/email/
Traceback (most recent call last):
  File "/Library/Frameworks/Python.framework/Versions/3.6/lib/python3.6/site-packages/django/core/handlers/exception.py", line 47, in inner
    response = get_response(request)
  File "/Library/Frameworks/Python.framework/Versions/3.6/lib/python3.6/site-packages/django/core/handlers/base.py", line 179, in _get_response
    response = wrapped_callback(request, *callback_args, **callback_kwargs)
  File "/Users/wuhongbin/Desktop/养乐多/lwjTest/apps/report/views.py", line 50, in reportDetails
    return render(request,"report/{}".format(name))
  File "/Library/Frameworks/Python.framework/Versions/3.6/lib/python3.6/site-packages/django/shortcuts.py", line 19, in render
    content = loader.render_to_string(template_name, context, request, using=using)
  File "/Library/Frameworks/Python.framework/Versions/3.6/lib/python3.6/site-packages/django/template/loader.py", line 61, in render_to_string
    template = get_template(template_name, using=using)
  File "/Library/Frameworks/Python.framework/Versions/3.6/lib/python3.6/site-packages/django/template/loader.py", line 19, in get_template
    raise TemplateDoesNotExist(template_name, chain=chain)
django.template.exceptions.TemplateDoesNotExist: report/email
2022-05-07 14:31:10 base.py[line:166] INFO Scheduler started
2022-05-07 14:32:02 log.py[line:230] WARNING Not Found: /report/fusion_report-2022-04-26-16-57-40
2022-05-07 14:32:03 log.py[line:230] WARNING Not Found: /favicon.ico
2022-05-07 14:32:15 log.py[line:230] WARNING Not Found: /report/fusion_report-2022-04-26-16-57-40/
2022-05-07 14:32:59 autoreload.py[line:236] INFO /Users/wuhongbin/Desktop/养乐多/lwjTest/apps/report/urls.py changed, reloading.
2022-05-07 14:33:03 base.py[line:166] INFO Scheduler started
2022-05-07 14:33:05 log.py[line:230] ERROR Internal Server Error: /report/fusion_report-2022-04-26-16-57-40/
Traceback (most recent call last):
  File "/Library/Frameworks/Python.framework/Versions/3.6/lib/python3.6/site-packages/django/core/handlers/exception.py", line 47, in inner
    response = get_response(request)
  File "/Library/Frameworks/Python.framework/Versions/3.6/lib/python3.6/site-packages/django/core/handlers/base.py", line 179, in _get_response
    response = wrapped_callback(request, *callback_args, **callback_kwargs)
  File "/Users/wuhongbin/Desktop/养乐多/lwjTest/apps/report/views.py", line 50, in reportDetails
    return render(request,"report/{}".format(name))
  File "/Library/Frameworks/Python.framework/Versions/3.6/lib/python3.6/site-packages/django/shortcuts.py", line 19, in render
    content = loader.render_to_string(template_name, context, request, using=using)
  File "/Library/Frameworks/Python.framework/Versions/3.6/lib/python3.6/site-packages/django/template/loader.py", line 61, in render_to_string
    template = get_template(template_name, using=using)
  File "/Library/Frameworks/Python.framework/Versions/3.6/lib/python3.6/site-packages/django/template/loader.py", line 19, in get_template
    raise TemplateDoesNotExist(template_name, chain=chain)
django.template.exceptions.TemplateDoesNotExist: report/fusion_report-2022-04-26-16-57-40
2022-05-07 14:35:21 base.py[line:166] INFO Scheduler started
2022-05-07 14:36:47 log.py[line:230] WARNING Method Not Allowed: /report/email/
2022-05-07 14:39:13 autoreload.py[line:236] INFO /Users/wuhongbin/Desktop/养乐多/lwjTest/apps/report/views.py changed, reloading.
2022-05-07 14:39:16 base.py[line:166] INFO Scheduler started
2022-05-07 14:39:50 autoreload.py[line:236] INFO /Users/wuhongbin/Desktop/养乐多/lwjTest/apps/report/views.py changed, reloading.
2022-05-07 14:40:08 base.py[line:166] INFO Scheduler started
2022-05-07 14:40:10 autoreload.py[line:236] INFO /Users/wuhongbin/Desktop/养乐多/lwjTest/apps/report/views.py changed, reloading.
2022-05-07 14:40:11 base.py[line:166] INFO Scheduler started
2022-05-07 14:42:07 autoreload.py[line:236] INFO /Users/wuhongbin/Desktop/养乐多/lwjTest/apps/report/views.py changed, reloading.
2022-05-07 14:42:54 base.py[line:166] INFO Scheduler started
2022-05-15 15:45:04 base.py[line:166] INFO Scheduler started
2022-05-15 15:46:20 log.py[line:230] ERROR Internal Server Error: /report/email
Traceback (most recent call last):
  File "/Library/Frameworks/Python.framework/Versions/3.6/lib/python3.6/site-packages/django/core/handlers/exception.py", line 47, in inner
    response = get_response(request)
  File "/Library/Frameworks/Python.framework/Versions/3.6/lib/python3.6/site-packages/django/core/handlers/base.py", line 179, in _get_response
    response = wrapped_callback(request, *callback_args, **callback_kwargs)
  File "/Users/wuhongbin/Desktop/养乐多/lwjTest/apps/report/views.py", line 50, in reportDetails
    return render(request,"report/{}".format(name))
  File "/Library/Frameworks/Python.framework/Versions/3.6/lib/python3.6/site-packages/django/shortcuts.py", line 19, in render
    content = loader.render_to_string(template_name, context, request, using=using)
  File "/Library/Frameworks/Python.framework/Versions/3.6/lib/python3.6/site-packages/django/template/loader.py", line 61, in render_to_string
    template = get_template(template_name, using=using)
  File "/Library/Frameworks/Python.framework/Versions/3.6/lib/python3.6/site-packages/django/template/loader.py", line 19, in get_template
    raise TemplateDoesNotExist(template_name, chain=chain)
django.template.exceptions.TemplateDoesNotExist: report/email
2022-05-15 15:46:31 log.py[line:230] WARNING Bad Request: /report/email/
2022-05-15 15:55:29 log.py[line:230] WARNING Bad Request: /login
2022-05-15 15:55:41 log.py[line:230] WARNING Bad Request: /login
2022-05-15 15:56:51 log.py[line:230] WARNING Bad Request: /chandao/case/
2022-05-15 15:58:30 log.py[line:230] WARNING Bad Request: /chandao/case/
2022-05-15 15:58:37 log.py[line:230] WARNING Bad Request: /chandao/case/
2022-05-15 15:58:51 log.py[line:230] ERROR Internal Server Error: /chandao/case/1/
Traceback (most recent call last):
  File "/Library/Frameworks/Python.framework/Versions/3.6/lib/python3.6/site-packages/django/core/handlers/exception.py", line 47, in inner
    response = get_response(request)
  File "/Library/Frameworks/Python.framework/Versions/3.6/lib/python3.6/site-packages/django/core/handlers/base.py", line 179, in _get_response
    response = wrapped_callback(request, *callback_args, **callback_kwargs)
  File "/Library/Frameworks/Python.framework/Versions/3.6/lib/python3.6/site-packages/django/views/decorators/csrf.py", line 54, in wrapped_view
    return view_func(*args, **kwargs)
  File "/Library/Frameworks/Python.framework/Versions/3.6/lib/python3.6/site-packages/rest_framework/viewsets.py", line 114, in view
    return self.dispatch(request, *args, **kwargs)
  File "/Library/Frameworks/Python.framework/Versions/3.6/lib/python3.6/site-packages/rest_framework/views.py", line 521, in dispatch
    response = self.handle_exception(exc)
  File "/Library/Frameworks/Python.framework/Versions/3.6/lib/python3.6/site-packages/rest_framework/views.py", line 477, in handle_exception
    self.raise_uncaught_exception(exc)
  File "/Library/Frameworks/Python.framework/Versions/3.6/lib/python3.6/site-packages/rest_framework/views.py", line 488, in raise_uncaught_exception
    raise exc
  File "/Library/Frameworks/Python.framework/Versions/3.6/lib/python3.6/site-packages/rest_framework/views.py", line 518, in dispatch
    response = handler(request, *args, **kwargs)
  File "/Library/Frameworks/Python.framework/Versions/3.6/lib/python3.6/site-packages/rest_framework/mixins.py", line 68, in update
    self.perform_update(serializer)
  File "/Library/Frameworks/Python.framework/Versions/3.6/lib/python3.6/site-packages/rest_framework/mixins.py", line 78, in perform_update
    serializer.save()
  File "/Library/Frameworks/Python.framework/Versions/3.6/lib/python3.6/site-packages/rest_framework/serializers.py", line 207, in save
    self.instance = self.update(self.instance, validated_data)
  File "/Users/wuhongbin/Desktop/养乐多/lwjTest/apps/chanDao/serializers.py", line 65, in update
    ChanDaoCaseStep.objects.create(case=instance, **case_step)
TypeError: create() got multiple values for keyword argument 'case'
2022-05-15 15:58:57 log.py[line:230] WARNING Not Found: /chandao/case/undefined/
2022-05-15 16:13:35 log.py[line:230] WARNING Not Found: /favicon.ico
2022-05-15 16:17:41 autoreload.py[line:236] INFO /Users/wuhongbin/Desktop/养乐多/lwjTest/apps/report/views.py changed, reloading.
2022-05-15 16:17:59 base.py[line:166] INFO Scheduler started
2022-05-15 16:24:47 log.py[line:230] WARNING Not Found: /lwj/sales/
2022-05-15 16:24:54 log.py[line:230] ERROR Internal Server Error: /chandao/excel/down/
Traceback (most recent call last):
  File "/Library/Frameworks/Python.framework/Versions/3.6/lib/python3.6/site-packages/django/core/handlers/exception.py", line 47, in inner
    response = get_response(request)
  File "/Library/Frameworks/Python.framework/Versions/3.6/lib/python3.6/site-packages/django/core/handlers/base.py", line 179, in _get_response
    response = wrapped_callback(request, *callback_args, **callback_kwargs)
  File "/Library/Frameworks/Python.framework/Versions/3.6/lib/python3.6/site-packages/django/views/decorators/csrf.py", line 54, in wrapped_view
    return view_func(*args, **kwargs)
  File "/Library/Frameworks/Python.framework/Versions/3.6/lib/python3.6/site-packages/django/views/generic/base.py", line 70, in view
    return self.dispatch(request, *args, **kwargs)
  File "/Library/Frameworks/Python.framework/Versions/3.6/lib/python3.6/site-packages/rest_framework/views.py", line 521, in dispatch
    response = self.handle_exception(exc)
  File "/Library/Frameworks/Python.framework/Versions/3.6/lib/python3.6/site-packages/rest_framework/views.py", line 477, in handle_exception
    self.raise_uncaught_exception(exc)
  File "/Library/Frameworks/Python.framework/Versions/3.6/lib/python3.6/site-packages/rest_framework/views.py", line 488, in raise_uncaught_exception
    raise exc
  File "/Library/Frameworks/Python.framework/Versions/3.6/lib/python3.6/site-packages/rest_framework/views.py", line 518, in dispatch
    response = handler(request, *args, **kwargs)
  File "/Users/wuhongbin/Desktop/养乐多/lwjTest/apps/chanDao/views.py", line 353, in get
    file = open(path, 'rb')
FileNotFoundError: [Errno 2] No such file or directory: '/Users/wuhongbin/Desktop/养乐多/lwjTest/apps/../static/file/test.xls'
2022-05-15 16:26:57 base.py[line:166] INFO Scheduler started
2022-05-15 16:27:22 autoreload.py[line:236] INFO /Users/wuhongbin/Desktop/养乐多/lwjTest/apps/chanDao/views.py changed, reloading.
2022-05-15 16:27:24 base.py[line:166] INFO Scheduler started
2022-05-15 16:35:09 base.py[line:166] INFO Scheduler started
2022-05-15 16:35:49 base.py[line:166] INFO Scheduler started
2022-05-15 16:36:23 base.py[line:166] INFO Scheduler started
2022-05-15 16:37:04 autoreload.py[line:236] INFO /Users/wuhongbin/Desktop/养乐多/lwjTest/apps/chanDao/views.py changed, reloading.
2022-05-15 16:37:06 base.py[line:166] INFO Scheduler started
2022-05-16 11:13:41 log.py[line:230] WARNING Not Found: /docs/
2022-05-16 11:14:01 log.py[line:230] WARNING Not Found: /chandao//chandao/excel/down/
2022-05-16 11:14:05 log.py[line:230] WARNING Not Found: /chandao/chandao/excel/down/
2022-05-16 11:15:30 base.py[line:166] INFO Scheduler started
2022-05-16 11:15:33 log.py[line:230] WARNING Not Found: /chandao/chandao/excel/down/
2022-05-16 11:15:36 log.py[line:230] WARNING Not Found: /chandao/chandao/excel/down/
2022-05-16 11:15:54 log.py[line:230] WARNING Not Found: /chandao/chandao/excel/down/
2022-05-16 11:16:32 base.py[line:166] INFO Scheduler started
2022-05-16 11:16:35 log.py[line:230] WARNING Not Found: /chandao/chandao/excel/down/
2022-05-16 11:16:50 base.py[line:166] INFO Scheduler started
2022-05-16 11:17:10 base.py[line:166] INFO Scheduler started
2022-05-16 11:19:45 autoreload.py[line:236] INFO /Users/wuhongbin/Desktop/养乐多/lwjTest/apps/chanDao/views.py changed, reloading.
2022-05-16 11:19:47 base.py[line:166] INFO Scheduler started
2022-05-16 11:20:05 base.py[line:166] INFO Scheduler started
2022-05-16 11:20:11 log.py[line:230] ERROR Internal Server Error: /chandao/excel/down/
Traceback (most recent call last):
  File "/Library/Frameworks/Python.framework/Versions/3.6/lib/python3.6/site-packages/django/core/handlers/exception.py", line 47, in inner
    response = get_response(request)
  File "/Library/Frameworks/Python.framework/Versions/3.6/lib/python3.6/site-packages/django/core/handlers/base.py", line 179, in _get_response
    response = wrapped_callback(request, *callback_args, **callback_kwargs)
  File "/Library/Frameworks/Python.framework/Versions/3.6/lib/python3.6/site-packages/django/views/decorators/csrf.py", line 54, in wrapped_view
    return view_func(*args, **kwargs)
  File "/Library/Frameworks/Python.framework/Versions/3.6/lib/python3.6/site-packages/django/views/generic/base.py", line 70, in view
    return self.dispatch(request, *args, **kwargs)
  File "/Library/Frameworks/Python.framework/Versions/3.6/lib/python3.6/site-packages/rest_framework/views.py", line 521, in dispatch
    response = self.handle_exception(exc)
  File "/Library/Frameworks/Python.framework/Versions/3.6/lib/python3.6/site-packages/rest_framework/views.py", line 477, in handle_exception
    self.raise_uncaught_exception(exc)
  File "/Library/Frameworks/Python.framework/Versions/3.6/lib/python3.6/site-packages/rest_framework/views.py", line 488, in raise_uncaught_exception
    raise exc
  File "/Library/Frameworks/Python.framework/Versions/3.6/lib/python3.6/site-packages/rest_framework/views.py", line 518, in dispatch
    response = handler(request, *args, **kwargs)
  File "/Users/wuhongbin/Desktop/养乐多/lwjTest/apps/chanDao/views.py", line 358, in get
    response['Content-Disposition'] = 'attachment;filename={}'.format(os.path.basename(file))
  File "/Library/Frameworks/Python.framework/Versions/3.6/lib/python3.6/posixpath.py", line 146, in basename
    p = os.fspath(p)
TypeError: expected str, bytes or os.PathLike object, not _io.BufferedReader
2022-05-16 11:20:35 base.py[line:166] INFO Scheduler started
2022-05-16 11:23:42 base.py[line:166] INFO Scheduler started
2022-05-16 11:24:07 base.py[line:166] INFO Scheduler started
2022-05-16 11:26:19 base.py[line:166] INFO Scheduler started
2022-05-16 11:26:49 base.py[line:166] INFO Scheduler started
2022-05-16 11:27:51 autoreload.py[line:236] INFO /Users/wuhongbin/Desktop/养乐多/lwjTest/apps/chanDao/views.py changed, reloading.
2022-05-16 11:27:53 base.py[line:166] INFO Scheduler started
2022-05-16 11:28:05 autoreload.py[line:236] INFO /Users/wuhongbin/Desktop/养乐多/lwjTest/apps/chanDao/views.py changed, reloading.
2022-05-16 11:28:07 base.py[line:166] INFO Scheduler started
2022-05-16 11:28:14 autoreload.py[line:236] INFO /Users/wuhongbin/Desktop/养乐多/lwjTest/apps/chanDao/views.py changed, reloading.
2022-05-16 11:28:17 base.py[line:166] INFO Scheduler started
2022-05-16 11:28:28 autoreload.py[line:236] INFO /Users/wuhongbin/Desktop/养乐多/lwjTest/apps/chanDao/views.py changed, reloading.
2022-05-16 11:28:33 base.py[line:166] INFO Scheduler started
2022-05-16 11:28:55 autoreload.py[line:236] INFO /Users/wuhongbin/Desktop/养乐多/lwjTest/apps/chanDao/views.py changed, reloading.
2022-05-16 11:28:57 base.py[line:166] INFO Scheduler started
2022-05-16 11:29:44 base.py[line:166] INFO Scheduler started
2022-05-16 11:37:17 autoreload.py[line:236] INFO /Users/wuhongbin/Desktop/养乐多/lwjTest/apps/chanDao/views.py changed, reloading.
2022-05-16 11:37:54 base.py[line:166] INFO Scheduler started
2022-05-16 11:38:25 base.py[line:166] INFO Scheduler started
2022-05-16 11:43:56 log.py[line:230] WARNING Not Found: /lwj/sales/
2022-05-16 11:44:00 log.py[line:230] WARNING Not Found: /chandao/sales/
2022-05-20 09:57:26 base.py[line:166] INFO Scheduler started
2022-05-20 10:23:35 log.py[line:230] WARNING Bad Request: /login
2022-05-20 10:23:39 log.py[line:230] WARNING Bad Request: /login
2022-05-20 10:23:40 log.py[line:230] WARNING Bad Request: /login
2022-05-20 10:23:40 log.py[line:230] WARNING Bad Request: /login
2022-05-20 10:23:43 log.py[line:230] WARNING Bad Request: /login
2022-05-20 10:34:28 log.py[line:230] WARNING Bad Request: /chandao/case/
2022-05-20 16:43:19 log.py[line:230] ERROR Internal Server Error: /chandao/case/2/
Traceback (most recent call last):
  File "/Library/Frameworks/Python.framework/Versions/3.6/lib/python3.6/site-packages/django/core/handlers/exception.py", line 47, in inner
    response = get_response(request)
  File "/Library/Frameworks/Python.framework/Versions/3.6/lib/python3.6/site-packages/django/core/handlers/base.py", line 179, in _get_response
    response = wrapped_callback(request, *callback_args, **callback_kwargs)
  File "/Library/Frameworks/Python.framework/Versions/3.6/lib/python3.6/site-packages/django/views/decorators/csrf.py", line 54, in wrapped_view
    return view_func(*args, **kwargs)
  File "/Library/Frameworks/Python.framework/Versions/3.6/lib/python3.6/site-packages/rest_framework/viewsets.py", line 114, in view
    return self.dispatch(request, *args, **kwargs)
  File "/Library/Frameworks/Python.framework/Versions/3.6/lib/python3.6/site-packages/rest_framework/views.py", line 521, in dispatch
    response = self.handle_exception(exc)
  File "/Library/Frameworks/Python.framework/Versions/3.6/lib/python3.6/site-packages/rest_framework/views.py", line 477, in handle_exception
    self.raise_uncaught_exception(exc)
  File "/Library/Frameworks/Python.framework/Versions/3.6/lib/python3.6/site-packages/rest_framework/views.py", line 488, in raise_uncaught_exception
    raise exc
  File "/Library/Frameworks/Python.framework/Versions/3.6/lib/python3.6/site-packages/rest_framework/views.py", line 518, in dispatch
    response = handler(request, *args, **kwargs)
  File "/Library/Frameworks/Python.framework/Versions/3.6/lib/python3.6/site-packages/rest_framework/mixins.py", line 68, in update
    self.perform_update(serializer)
  File "/Library/Frameworks/Python.framework/Versions/3.6/lib/python3.6/site-packages/rest_framework/mixins.py", line 78, in perform_update
    serializer.save()
  File "/Library/Frameworks/Python.framework/Versions/3.6/lib/python3.6/site-packages/rest_framework/serializers.py", line 207, in save
    self.instance = self.update(self.instance, validated_data)
  File "/Users/wuhongbin/Desktop/养乐多/lwjTest/apps/chanDao/serializers.py", line 65, in update
    ChanDaoCaseStep.objects.create(case=instance, **case_step)
TypeError: create() got multiple values for keyword argument 'case'
2022-05-20 16:43:29 log.py[line:230] WARNING Not Found: /chandao/case/undefined/
2022-05-20 16:43:31 log.py[line:230] WARNING Not Found: /chandao/case/undefined/
2022-05-20 16:43:59 log.py[line:230] WARNING Not Found: /chandao/case/undefined/
2022-05-20 16:44:23 log.py[line:230] WARNING Not Found: /chandao/case/undefined/
2022-05-20 16:50:59 log.py[line:230] WARNING Bad Request: /chandao/case/2/
2022-05-20 16:51:00 log.py[line:230] WARNING Bad Request: /chandao/case/2/
2022-05-20 16:51:00 log.py[line:230] WARNING Bad Request: /chandao/case/2/
2022-05-20 16:51:01 log.py[line:230] WARNING Bad Request: /chandao/case/2/
2022-05-20 16:51:02 log.py[line:230] WARNING Bad Request: /chandao/case/2/
2022-05-20 16:51:02 log.py[line:230] WARNING Bad Request: /chandao/case/2/
2022-05-20 16:51:03 log.py[line:230] WARNING Bad Request: /chandao/case/2/
2022-05-20 16:51:03 log.py[line:230] WARNING Bad Request: /chandao/case/2/
2022-05-20 16:59:56 log.py[line:230] WARNING Method Not Allowed: /chandao/case/1/
2022-05-20 17:02:54 log.py[line:230] WARNING Not Found: /chandao/case/undefined/
2022-05-20 17:20:15 base.py[line:166] INFO Scheduler started
2022-05-21 21:25:30 base.py[line:166] INFO Scheduler started
2022-05-21 21:26:40 log.py[line:230] WARNING Method Not Allowed: /chandao/case/1/
2022-05-21 21:26:41 log.py[line:230] WARNING Method Not Allowed: /chandao/case/1/
2022-05-21 21:32:33 log.py[line:230] ERROR Internal Server Error: /chandao/excel/down/
Traceback (most recent call last):
  File "/Library/Frameworks/Python.framework/Versions/3.6/lib/python3.6/site-packages/django/core/handlers/exception.py", line 47, in inner
    response = get_response(request)
  File "/Library/Frameworks/Python.framework/Versions/3.6/lib/python3.6/site-packages/django/core/handlers/base.py", line 179, in _get_response
    response = wrapped_callback(request, *callback_args, **callback_kwargs)
  File "/Library/Frameworks/Python.framework/Versions/3.6/lib/python3.6/site-packages/django/views/decorators/csrf.py", line 54, in wrapped_view
    return view_func(*args, **kwargs)
  File "/Library/Frameworks/Python.framework/Versions/3.6/lib/python3.6/site-packages/django/views/generic/base.py", line 70, in view
    return self.dispatch(request, *args, **kwargs)
  File "/Library/Frameworks/Python.framework/Versions/3.6/lib/python3.6/site-packages/rest_framework/views.py", line 521, in dispatch
    response = self.handle_exception(exc)
  File "/Library/Frameworks/Python.framework/Versions/3.6/lib/python3.6/site-packages/rest_framework/views.py", line 477, in handle_exception
    self.raise_uncaught_exception(exc)
  File "/Library/Frameworks/Python.framework/Versions/3.6/lib/python3.6/site-packages/rest_framework/views.py", line 488, in raise_uncaught_exception
    raise exc
  File "/Library/Frameworks/Python.framework/Versions/3.6/lib/python3.6/site-packages/rest_framework/views.py", line 518, in dispatch
    response = handler(request, *args, **kwargs)
  File "/Users/wuhongbin/Desktop/养乐多/lwjTest/apps/chanDao/views.py", line 355, in get
    file = open(path, 'rb')
FileNotFoundError: [Errno 2] No such file or directory: '/Users/wuhongbin/Desktop/养乐多/lwjTest/apps/../templates/测试用例.xls'
2022-05-21 21:32:45 log.py[line:230] ERROR Internal Server Error: /chandao/excel/down/
Traceback (most recent call last):
  File "/Library/Frameworks/Python.framework/Versions/3.6/lib/python3.6/site-packages/django/core/handlers/exception.py", line 47, in inner
    response = get_response(request)
  File "/Library/Frameworks/Python.framework/Versions/3.6/lib/python3.6/site-packages/django/core/handlers/base.py", line 179, in _get_response
    response = wrapped_callback(request, *callback_args, **callback_kwargs)
  File "/Library/Frameworks/Python.framework/Versions/3.6/lib/python3.6/site-packages/django/views/decorators/csrf.py", line 54, in wrapped_view
    return view_func(*args, **kwargs)
  File "/Library/Frameworks/Python.framework/Versions/3.6/lib/python3.6/site-packages/django/views/generic/base.py", line 70, in view
    return self.dispatch(request, *args, **kwargs)
  File "/Library/Frameworks/Python.framework/Versions/3.6/lib/python3.6/site-packages/rest_framework/views.py", line 521, in dispatch
    response = self.handle_exception(exc)
  File "/Library/Frameworks/Python.framework/Versions/3.6/lib/python3.6/site-packages/rest_framework/views.py", line 477, in handle_exception
    self.raise_uncaught_exception(exc)
  File "/Library/Frameworks/Python.framework/Versions/3.6/lib/python3.6/site-packages/rest_framework/views.py", line 488, in raise_uncaught_exception
    raise exc
  File "/Library/Frameworks/Python.framework/Versions/3.6/lib/python3.6/site-packages/rest_framework/views.py", line 518, in dispatch
    response = handler(request, *args, **kwargs)
  File "/Users/wuhongbin/Desktop/养乐多/lwjTest/apps/chanDao/views.py", line 355, in get
    file = open(path, 'rb')
FileNotFoundError: [Errno 2] No such file or directory: '/Users/wuhongbin/Desktop/养乐多/lwjTest/apps/../templates/测试用例.xls'
2022-05-21 21:32:55 log.py[line:230] ERROR Internal Server Error: /chandao/excel/down/
Traceback (most recent call last):
  File "/Library/Frameworks/Python.framework/Versions/3.6/lib/python3.6/site-packages/django/core/handlers/exception.py", line 47, in inner
    response = get_response(request)
  File "/Library/Frameworks/Python.framework/Versions/3.6/lib/python3.6/site-packages/django/core/handlers/base.py", line 179, in _get_response
    response = wrapped_callback(request, *callback_args, **callback_kwargs)
  File "/Library/Frameworks/Python.framework/Versions/3.6/lib/python3.6/site-packages/django/views/decorators/csrf.py", line 54, in wrapped_view
    return view_func(*args, **kwargs)
  File "/Library/Frameworks/Python.framework/Versions/3.6/lib/python3.6/site-packages/django/views/generic/base.py", line 70, in view
    return self.dispatch(request, *args, **kwargs)
  File "/Library/Frameworks/Python.framework/Versions/3.6/lib/python3.6/site-packages/rest_framework/views.py", line 521, in dispatch
    response = self.handle_exception(exc)
  File "/Library/Frameworks/Python.framework/Versions/3.6/lib/python3.6/site-packages/rest_framework/views.py", line 477, in handle_exception
    self.raise_uncaught_exception(exc)
  File "/Library/Frameworks/Python.framework/Versions/3.6/lib/python3.6/site-packages/rest_framework/views.py", line 488, in raise_uncaught_exception
    raise exc
  File "/Library/Frameworks/Python.framework/Versions/3.6/lib/python3.6/site-packages/rest_framework/views.py", line 518, in dispatch
    response = handler(request, *args, **kwargs)
  File "/Users/wuhongbin/Desktop/养乐多/lwjTest/apps/chanDao/views.py", line 355, in get
    file = open(path, 'rb')
FileNotFoundError: [Errno 2] No such file or directory: '/Users/wuhongbin/Desktop/养乐多/lwjTest/apps/../templates/测试用例.xls'
2022-05-21 21:33:05 log.py[line:230] ERROR Internal Server Error: /chandao/excel/down/
Traceback (most recent call last):
  File "/Library/Frameworks/Python.framework/Versions/3.6/lib/python3.6/site-packages/django/core/handlers/exception.py", line 47, in inner
    response = get_response(request)
  File "/Library/Frameworks/Python.framework/Versions/3.6/lib/python3.6/site-packages/django/core/handlers/base.py", line 179, in _get_response
    response = wrapped_callback(request, *callback_args, **callback_kwargs)
  File "/Library/Frameworks/Python.framework/Versions/3.6/lib/python3.6/site-packages/django/views/decorators/csrf.py", line 54, in wrapped_view
    return view_func(*args, **kwargs)
  File "/Library/Frameworks/Python.framework/Versions/3.6/lib/python3.6/site-packages/django/views/generic/base.py", line 70, in view
    return self.dispatch(request, *args, **kwargs)
  File "/Library/Frameworks/Python.framework/Versions/3.6/lib/python3.6/site-packages/rest_framework/views.py", line 521, in dispatch
    response = self.handle_exception(exc)
  File "/Library/Frameworks/Python.framework/Versions/3.6/lib/python3.6/site-packages/rest_framework/views.py", line 477, in handle_exception
    self.raise_uncaught_exception(exc)
  File "/Library/Frameworks/Python.framework/Versions/3.6/lib/python3.6/site-packages/rest_framework/views.py", line 488, in raise_uncaught_exception
    raise exc
  File "/Library/Frameworks/Python.framework/Versions/3.6/lib/python3.6/site-packages/rest_framework/views.py", line 518, in dispatch
    response = handler(request, *args, **kwargs)
  File "/Users/wuhongbin/Desktop/养乐多/lwjTest/apps/chanDao/views.py", line 355, in get
    file = open(path, 'rb')
FileNotFoundError: [Errno 2] No such file or directory: '/Users/wuhongbin/Desktop/养乐多/lwjTest/apps/../templates/测试用例.xls'
2022-05-21 21:46:46 log.py[line:230] WARNING Not Found: /import/case/
2022-05-21 21:50:55 log.py[line:230] WARNING Not Found: /import/case/
2022-05-21 21:51:53 log.py[line:230] WARNING Not Found: /import/case/
2022-05-21 21:53:28 log.py[line:230] WARNING Not Found: /import/case/
2022-05-21 22:26:36 log.py[line:230] WARNING Bad Request: /report/email/
2022-05-21 22:26:36 log.py[line:230] WARNING Bad Request: /report/email/
2022-05-21 22:48:30 log.py[line:230] WARNING Not Found: /report/email/undefined/
2022-05-21 22:52:11 log.py[line:230] WARNING Bad Request: /report/email/
2022-05-21 22:53:00 log.py[line:230] WARNING Bad Request: /report/email/
2022-05-21 22:53:19 log.py[line:230] WARNING Bad Request: /report/email/
2022-05-21 22:54:08 log.py[line:230] WARNING Bad Request: /report/email/
2022-05-21 23:13:43 log.py[line:230] ERROR Internal Server Error: /chandao/case/3/
Traceback (most recent call last):
  File "/Library/Frameworks/Python.framework/Versions/3.6/lib/python3.6/site-packages/django/core/handlers/exception.py", line 47, in inner
    response = get_response(request)
  File "/Library/Frameworks/Python.framework/Versions/3.6/lib/python3.6/site-packages/django/core/handlers/base.py", line 179, in _get_response
    response = wrapped_callback(request, *callback_args, **callback_kwargs)
  File "/Library/Frameworks/Python.framework/Versions/3.6/lib/python3.6/site-packages/django/views/decorators/csrf.py", line 54, in wrapped_view
    return view_func(*args, **kwargs)
  File "/Library/Frameworks/Python.framework/Versions/3.6/lib/python3.6/site-packages/rest_framework/viewsets.py", line 114, in view
    return self.dispatch(request, *args, **kwargs)
  File "/Library/Frameworks/Python.framework/Versions/3.6/lib/python3.6/site-packages/rest_framework/views.py", line 521, in dispatch
    response = self.handle_exception(exc)
  File "/Library/Frameworks/Python.framework/Versions/3.6/lib/python3.6/site-packages/rest_framework/views.py", line 477, in handle_exception
    self.raise_uncaught_exception(exc)
  File "/Library/Frameworks/Python.framework/Versions/3.6/lib/python3.6/site-packages/rest_framework/views.py", line 488, in raise_uncaught_exception
    raise exc
  File "/Library/Frameworks/Python.framework/Versions/3.6/lib/python3.6/site-packages/rest_framework/views.py", line 518, in dispatch
    response = handler(request, *args, **kwargs)
  File "/Library/Frameworks/Python.framework/Versions/3.6/lib/python3.6/site-packages/rest_framework/mixins.py", line 68, in update
    self.perform_update(serializer)
  File "/Library/Frameworks/Python.framework/Versions/3.6/lib/python3.6/site-packages/rest_framework/mixins.py", line 78, in perform_update
    serializer.save()
  File "/Library/Frameworks/Python.framework/Versions/3.6/lib/python3.6/site-packages/rest_framework/serializers.py", line 207, in save
    self.instance = self.update(self.instance, validated_data)
  File "/Users/wuhongbin/Desktop/养乐多/lwjTest/apps/chanDao/serializers.py", line 65, in update
    ChanDaoCaseStep.objects.create(case=instance, **case_step)
TypeError: create() got multiple values for keyword argument 'case'
2022-05-23 10:24:26 base.py[line:166] INFO Scheduler started
2022-05-23 10:25:01 log.py[line:230] WARNING Forbidden: /api/host/
2022-05-23 10:25:01 log.py[line:230] WARNING Forbidden: /api/api/
2022-05-23 10:25:01 log.py[line:230] WARNING Forbidden: /api/project/
2022-05-23 10:26:13 base.py[line:166] INFO Scheduler started
2022-05-23 10:27:18 base.py[line:166] INFO Scheduler started
2022-05-23 10:59:48 log.py[line:230] WARNING Bad Request: /login
2022-05-23 10:59:50 log.py[line:230] WARNING Forbidden: /api/project/
2022-05-23 10:59:51 log.py[line:230] WARNING Forbidden: /api/project/1/
2022-05-23 10:59:51 log.py[line:230] WARNING Forbidden: /api/project/1/
2022-05-23 16:26:01 base.py[line:166] INFO Scheduler started
2022-05-23 16:28:18 log.py[line:230] ERROR Internal Server Error: /chandao/excel/down/
Traceback (most recent call last):
  File "/Library/Frameworks/Python.framework/Versions/3.6/lib/python3.6/site-packages/django/core/handlers/exception.py", line 47, in inner
    response = get_response(request)
  File "/Library/Frameworks/Python.framework/Versions/3.6/lib/python3.6/site-packages/django/core/handlers/base.py", line 179, in _get_response
    response = wrapped_callback(request, *callback_args, **callback_kwargs)
  File "/Library/Frameworks/Python.framework/Versions/3.6/lib/python3.6/site-packages/django/views/decorators/csrf.py", line 54, in wrapped_view
    return view_func(*args, **kwargs)
  File "/Library/Frameworks/Python.framework/Versions/3.6/lib/python3.6/site-packages/django/views/generic/base.py", line 70, in view
    return self.dispatch(request, *args, **kwargs)
  File "/Library/Frameworks/Python.framework/Versions/3.6/lib/python3.6/site-packages/rest_framework/views.py", line 521, in dispatch
    response = self.handle_exception(exc)
  File "/Library/Frameworks/Python.framework/Versions/3.6/lib/python3.6/site-packages/rest_framework/views.py", line 477, in handle_exception
    self.raise_uncaught_exception(exc)
  File "/Library/Frameworks/Python.framework/Versions/3.6/lib/python3.6/site-packages/rest_framework/views.py", line 488, in raise_uncaught_exception
    raise exc
  File "/Library/Frameworks/Python.framework/Versions/3.6/lib/python3.6/site-packages/rest_framework/views.py", line 518, in dispatch
    response = handler(request, *args, **kwargs)
  File "/Users/wuhongbin/Desktop/养乐多/lwjTest/apps/chanDao/views.py", line 355, in get
    file = open(path, 'rb')
FileNotFoundError: [Errno 2] No such file or directory: '/Users/wuhongbin/Desktop/养乐多/lwjTest/apps/../templates/测试用例.xls'
2022-05-23 16:30:36 base.py[line:166] INFO Scheduler started
2022-05-23 16:33:07 log.py[line:230] WARNING Bad Request: /chandao/case/
2022-05-23 16:33:08 log.py[line:230] WARNING Bad Request: /chandao/case/
2022-05-23 16:33:13 log.py[line:230] WARNING Bad Request: /chandao/case/
2022-05-24 17:31:05 base.py[line:166] INFO Scheduler started
2022-05-24 17:35:30 base.py[line:166] INFO Scheduler started
2022-05-24 17:35:45 autoreload.py[line:236] INFO /Users/wuhongbin/Desktop/养乐多/lwjTest/lwjTest/settings.py changed, reloading.
2022-05-24 17:35:47 base.py[line:166] INFO Scheduler started
2022-06-01 11:18:55 base.py[line:166] INFO Scheduler started
2022-06-01 11:20:33 log.py[line:230] WARNING Bad Request: /login
2022-06-01 11:27:31 autoreload.py[line:236] INFO /Users/wuhongbin/Desktop/养乐多/lwjTest/lwjTest/settings.py changed, reloading.
2022-06-01 11:27:34 base.py[line:166] INFO Scheduler started
2022-06-01 11:27:48 log.py[line:230] ERROR Internal Server Error: /sms/smsCode/13683450131
Traceback (most recent call last):
  File "/Library/Frameworks/Python.framework/Versions/3.6/lib/python3.6/site-packages/redis/connection.py", line 559, in connect
    sock = self._connect()
  File "/Library/Frameworks/Python.framework/Versions/3.6/lib/python3.6/site-packages/redis/connection.py", line 615, in _connect
    raise err
  File "/Library/Frameworks/Python.framework/Versions/3.6/lib/python3.6/site-packages/redis/connection.py", line 603, in _connect
    sock.connect(socket_address)
ConnectionRefusedError: [Errno 61] Connection refused

During handling of the above exception, another exception occurred:

Traceback (most recent call last):
  File "/Library/Frameworks/Python.framework/Versions/3.6/lib/python3.6/site-packages/django/core/handlers/exception.py", line 47, in inner
    response = get_response(request)
  File "/Library/Frameworks/Python.framework/Versions/3.6/lib/python3.6/site-packages/django/core/handlers/base.py", line 179, in _get_response
    response = wrapped_callback(request, *callback_args, **callback_kwargs)
  File "/Library/Frameworks/Python.framework/Versions/3.6/lib/python3.6/site-packages/django/views/decorators/csrf.py", line 54, in wrapped_view
    return view_func(*args, **kwargs)
  File "/Library/Frameworks/Python.framework/Versions/3.6/lib/python3.6/site-packages/django/views/generic/base.py", line 70, in view
    return self.dispatch(request, *args, **kwargs)
  File "/Library/Frameworks/Python.framework/Versions/3.6/lib/python3.6/site-packages/rest_framework/views.py", line 521, in dispatch
    response = self.handle_exception(exc)
  File "/Library/Frameworks/Python.framework/Versions/3.6/lib/python3.6/site-packages/rest_framework/views.py", line 477, in handle_exception
    self.raise_uncaught_exception(exc)
  File "/Library/Frameworks/Python.framework/Versions/3.6/lib/python3.6/site-packages/rest_framework/views.py", line 488, in raise_uncaught_exception
    raise exc
  File "/Library/Frameworks/Python.framework/Versions/3.6/lib/python3.6/site-packages/rest_framework/views.py", line 518, in dispatch
    response = handler(request, *args, **kwargs)
  File "/Users/wuhongbin/Desktop/养乐多/lwjTest/apps/verification/views.py", line 24, in post
    send_mobile = redis_conn.get("send_{}".format(mobile))
  File "/Library/Frameworks/Python.framework/Versions/3.6/lib/python3.6/site-packages/redis/client.py", line 1606, in get
    return self.execute_command('GET', name)
  File "/Library/Frameworks/Python.framework/Versions/3.6/lib/python3.6/site-packages/redis/client.py", line 898, in execute_command
    conn = self.connection or pool.get_connection(command_name, **options)
  File "/Library/Frameworks/Python.framework/Versions/3.6/lib/python3.6/site-packages/redis/connection.py", line 1192, in get_connection
    connection.connect()
  File "/Library/Frameworks/Python.framework/Versions/3.6/lib/python3.6/site-packages/redis/connection.py", line 563, in connect
    raise ConnectionError(self._error_message(e))
redis.exceptions.ConnectionError: Error 61 connecting to 116.211.118.66:6379. Connection refused.
2022-06-01 13:40:51 log.py[line:230] ERROR Internal Server Error: /sms/smsCode/13683450131
Traceback (most recent call last):
  File "/Library/Frameworks/Python.framework/Versions/3.6/lib/python3.6/site-packages/redis/connection.py", line 559, in connect
    sock = self._connect()
  File "/Library/Frameworks/Python.framework/Versions/3.6/lib/python3.6/site-packages/redis/connection.py", line 615, in _connect
    raise err
  File "/Library/Frameworks/Python.framework/Versions/3.6/lib/python3.6/site-packages/redis/connection.py", line 603, in _connect
    sock.connect(socket_address)
ConnectionRefusedError: [Errno 61] Connection refused

During handling of the above exception, another exception occurred:

Traceback (most recent call last):
  File "/Library/Frameworks/Python.framework/Versions/3.6/lib/python3.6/site-packages/django/core/handlers/exception.py", line 47, in inner
    response = get_response(request)
  File "/Library/Frameworks/Python.framework/Versions/3.6/lib/python3.6/site-packages/django/core/handlers/base.py", line 179, in _get_response
    response = wrapped_callback(request, *callback_args, **callback_kwargs)
  File "/Library/Frameworks/Python.framework/Versions/3.6/lib/python3.6/site-packages/django/views/decorators/csrf.py", line 54, in wrapped_view
    return view_func(*args, **kwargs)
  File "/Library/Frameworks/Python.framework/Versions/3.6/lib/python3.6/site-packages/django/views/generic/base.py", line 70, in view
    return self.dispatch(request, *args, **kwargs)
  File "/Library/Frameworks/Python.framework/Versions/3.6/lib/python3.6/site-packages/rest_framework/views.py", line 521, in dispatch
    response = self.handle_exception(exc)
  File "/Library/Frameworks/Python.framework/Versions/3.6/lib/python3.6/site-packages/rest_framework/views.py", line 477, in handle_exception
    self.raise_uncaught_exception(exc)
  File "/Library/Frameworks/Python.framework/Versions/3.6/lib/python3.6/site-packages/rest_framework/views.py", line 488, in raise_uncaught_exception
    raise exc
  File "/Library/Frameworks/Python.framework/Versions/3.6/lib/python3.6/site-packages/rest_framework/views.py", line 518, in dispatch
    response = handler(request, *args, **kwargs)
  File "/Users/wuhongbin/Desktop/养乐多/lwjTest/apps/verification/views.py", line 24, in post
    send_mobile = redis_conn.get("send_{}".format(mobile))
  File "/Library/Frameworks/Python.framework/Versions/3.6/lib/python3.6/site-packages/redis/client.py", line 1606, in get
    return self.execute_command('GET', name)
  File "/Library/Frameworks/Python.framework/Versions/3.6/lib/python3.6/site-packages/redis/client.py", line 898, in execute_command
    conn = self.connection or pool.get_connection(command_name, **options)
  File "/Library/Frameworks/Python.framework/Versions/3.6/lib/python3.6/site-packages/redis/connection.py", line 1192, in get_connection
    connection.connect()
  File "/Library/Frameworks/Python.framework/Versions/3.6/lib/python3.6/site-packages/redis/connection.py", line 563, in connect
    raise ConnectionError(self._error_message(e))
redis.exceptions.ConnectionError: Error 61 connecting to 116.211.118.66:6379. Connection refused.
2022-06-01 13:43:39 base.py[line:166] INFO Scheduler started
2022-06-02 14:30:28 base.py[line:166] INFO Scheduler started
2022-06-02 15:59:50 base.py[line:166] INFO Scheduler started
2022-06-02 16:02:28 base.py[line:166] INFO Scheduler started
2022-06-02 16:04:39 base.py[line:166] INFO Scheduler started
2022-06-02 16:06:10 base.py[line:166] INFO Scheduler started
2022-06-02 16:11:41 base.py[line:166] INFO Scheduler started
2022-06-02 16:12:20 base.py[line:166] INFO Scheduler started
2022-06-02 16:12:34 base.py[line:166] INFO Scheduler started
2022-06-02 16:13:38 base.py[line:166] INFO Scheduler started
2022-06-02 16:13:56 base.py[line:166] INFO Scheduler started
